Workbook

Sheet Inputs
A1: Category | B1: Input key | C1: Value | D1: Unit | E1: Classification | F1: Exact tag / source | G1: Accession / source date / note
A2: SEC fact | B2: AAPL_Revenue_FY2023 | C2: 383.285 | D2: USD bn | E2: Traced SEC fact | F2: RevenueFromContractWithCustomerExcludingAssessedTax | G2: 0000320193-23-000106
A3: SEC fact | B3: AAPL_EBIT_FY2023 | C3: 114.301 | D3: USD bn | E3: Traced SEC fact | F3: OperatingIncomeLoss | G3: 0000320193-23-000106
A4: SEC fact | B4: AAPL_Pretax_FY2023 | C4: 113.736 | D4: USD bn | E4: Traced SEC fact | F4: IncomeLossFromContinuingOperationsBeforeIncomeTaxesExtraordinaryItemsNoncontrollingInterest | G4: 0000320193-23-000106
A5: SEC fact | B5: AAPL_Tax_FY2023 | C5: 16.741 | D5: USD bn | E5: Traced SEC fact | F5: IncomeTaxExpenseBenefit | G5: 0000320193-23-000106
A6: SEC fact | B6: AAPL_DA_FY2023 | C6: 11.519 | D6: USD bn | E6: Traced SEC fact | F6: DepreciationDepletionAndAmortization | G6: 0000320193-23-000106
A7: SEC fact | B7: AAPL_Capex_FY2023 | C7: 10.959 | D7: USD bn | E7: Traced SEC fact | F7: PaymentsToAcquirePropertyPlantAndEquipment | G7: 0000320193-23-000106
A8: SEC fact | B8: AAPL_NetIncome_FY2023 | C8: 96.995 | D8: USD bn | E8: Traced SEC fact | F8: NetIncomeLoss | G8: 0000320193-23-000106
A9: SEC fact | B9: AAPL_DilutedShares_FY2023 | C9: 15.812547 | D9: shares bn | E9: Traced SEC fact | F9: WeightedAverageNumberOfDilutedSharesOutstanding | G9: 0000320193-23-000106
A10: SEC fact | B10: AAPL_Revenue_FY2024 | C10: 391.035 | D10: USD bn | E10: Traced SEC fact | F10: RevenueFromContractWithCustomerExcludingAssessedTax | G10: 0000320193-24-000123
A11: SEC fact | B11: AAPL_EBIT_FY2024 | C11: 123.216 | D11: USD bn | E11: Traced SEC fact | F11: OperatingIncomeLoss | G11: 0000320193-24-000123
A12: SEC fact | B12: AAPL_Pretax_FY2024 | C12: 123.485 | D12: USD bn | E12: Traced SEC fact | F12: IncomeLossFromContinuingOperationsBeforeIncomeTaxesExtraordinaryItemsNoncontrollingInterest | G12: 0000320193-24-000123
A13: SEC fact | B13: AAPL_Tax_FY2024 | C13: 29.749 | D13: USD bn | E13: Traced SEC fact | F13: IncomeTaxExpenseBenefit | G13: 0000320193-24-000123
... A71: Assumption | B71: LBO_HoldYears | C71: 5 | D71: years | E71: Proposed LBO assumption | F71: User-specified holding period | G71: Review pending
A72: Derived calculation | B72: AAPL_NWC_FY2025 | C72: =(C32-C26-C27)-(C33-C29-C30) | D72: USD bn | E72: Derived from SEC facts | F72: (AssetsCurrent - cash - current securities) - (current liabilities - current debt - commercial paper) | G72: 0000320193-25-000079
A73: Derived valuation input | B73: MSFT_EVRevenue_Multiple_Rounded | C73: 11.62 | D73: x | E73: Previously derived rounded peer multiple | F73: Microsoft EV / Revenue applied in Day 5 report | G73: Rounded from the already-established comps output
A74: Derived valuation input | B74: MSFT_EVEBITDA_Multiple_Rounded | C74: 19.86 | D74: x | E74: Previously derived rounded peer multiple | F74: Microsoft EV / EBITDA applied in Day 5 report | G74: Rounded from the already-established comps output
A75: Derived valuation input | B75: MSFT_PE_Multiple_Rounded | C75: 29.38 | D75: x | E75: Previously derived rounded peer multiple | F75: Microsoft P/E applied in Day 5 report | G75: Rounded from the already-established comps output
A76: Assumption | B76: LBO_TLBMaturityYears | C76: 7 | D76: years | E76: Proposed LBO assumption | F76: Term Loan B maturity | G76: Review pending
A77: Assumption | B77: LBO_NotesMaturityYears | C77: 10 | D77: years | E77: Proposed LBO assumption | F77: Senior notes maturity | G77: Review pending
A78: Assumption | B78: LBO_NotesScheduledAmort | C78: 0 | D78: % original debt | E78: Proposed LBO assumption | F78: No scheduled senior-note amortization during five-year hold | G78: Review pending
A79: Assumption | B79: LBO_CashSweepPct | C79: 1 | D79: % | E79: Proposed LBO assumption | F79: 100% excess cash sweep, TLB first, then notes | G79: Review pending
A80: Assumption | B80: LBO_MinimumCashReserve | C80: 0 | D80: USD bn | E80: Proposed LBO assumption | F80: No minimum cash reserve modeled | G80: Review pending
A81: Assumption | B81: LBO_InterimDistributions | C81: 0 | D81: USD bn | E81: Proposed LBO assumption | F81: No sponsor distributions during the hold | G81: Review pending
A82: SEC fact | B82: GOOGL_Revenue_FY2025 | C82: 402.836 | D82: USD bn | E82: Traced SEC fact | F82: Revenues | G82: 0001652044-26-000018
A83: SEC fact | B83: GOOGL_EBIT_FY2025 | C83: 129.039 | D83: USD bn | E83: Traced SEC fact | F83: OperatingIncomeLoss | G83: 0001652044-26-000018
A84: SEC fact | B84: GOOGL_Depreciation_FY2025 | C84: 21.136 | D84: USD bn | E84: Traced SEC fact | F84: Depreciation | G84: 0001652044-26-000018
A85: SEC fact | B85: GOOGL_NetIncome_FY2025 | C85: 132.17 | D85: USD bn | E85: Traced SEC fact | F85: NetIncomeLoss | G85: 0001652044-26-000018
A86: SEC fact | B86: GOOGL_Debt_identified_FY2025 | C86: =SUM('Inputs'!$C$137,'Inputs'!$C$138,'Inputs'!$C$88) | D86: USD bn | E86: Derived from traced SEC facts | F86: LongTermDebtCurrent + LongTermDebtNoncurrent + CommercialPaper | G86: 0001652044-26-000018
A87: SEC fact | B87: GOOGL_CashInvestments_FY2025 | C87: =SUM('Inputs'!$C$135,'Inputs'!$C$136) | D87: USD bn | E87: Derived from traced SEC facts | F87: CashCashEquivalentsAndShortTermInvestments + OtherLongTermInvestments; aggregate includes cash | G87: 0001652044-26-000018
A88: SEC fact | B88: GOOGL_CommercialPaper_FY2025 | C88: 0 | D88: USD bn | E88: Traced SEC fact | F88: CommercialPaper (reported fact) | G88: 0001652044-26-000018
A89: SEC fact | B89: AMZN_Revenue_FY2025 | C89: 716.924 | D89: USD bn | E89: Traced SEC fact | F89: RevenueFromContractWithCustomerExcludingAssessedTax | G89: 0001018724-26-000004
A90: SEC fact | B90: AMZN_EBIT_FY2025 | C90: 79.975 | D90: USD bn | E90: Traced SEC fact | F90: OperatingIncomeLoss | G90: 0001018724-26-000004
A91: SEC fact | B91: AMZN_Depreciation_FY2025 | C91: 41.86 | D91: USD bn | E91: Traced SEC fact | F91: Depreciation | G91: 0001018724-26-000004
A92: SEC fact | B92: AMZN_IntangibleAmortization_FY2025 | C92: 0.817 | D92: USD bn | E92: Traced SEC fact | F92: AmortizationOfIntangibleAssets | G92: 0001018724-26-000004
A93: SEC fact | B93: AMZN_NetIncome_FY2025 | C93: 77.67 | D93: USD bn | E93: Traced SEC fact | F93: NetIncomeLoss | G93: 0001018724-26-000004
A94: SEC fact | B94: AMZN_Debt_identified_FY2025 | C94: =SUM('Inputs'!$C$141,'Inputs'!$C$142) | D94: USD bn | E94: Derived from traced SEC facts | F94: LongTermDebtCurrent + LongTermDebtNoncurrent | G94: 0001018724-26-000004
A95: SEC fact | B95: AMZN_CashInvestments_FY2025 | C95: =SUM('Inputs'!$C$139,'Inputs'!$C$140) | D95: USD bn | E95: Derived from traced SEC facts | F95: CashAndCashEquivalentsAtCarryingValue + MarketableSecuritiesCurrent | G95: 0001018724-26-000004
A96: SEC fact | B96: AMZN_CommercialPaper_FY2025 | C96: Not found | D96: USD bn | E96: SEC fact unavailable in captured data | F96: CommercialPaper | G96: 0001018724-26-000004; no fact identified; not treated as zero
A97: SEC fact | B97: META_Revenue_FY2025 | C97: 200.966 | D97: USD bn | E97: Traced SEC fact | F97: RevenueFromContractWithCustomerExcludingAssessedTax | G97: 0001628280-26-003942
...

Sheet DCF
A1: DCF — USD bn except per-share values
A2: WACC build | B2: Value
A3: Cost of equity | B3: ='Inputs'!$C$47+'Inputs'!$C$48*'Inputs'!$C$49
A4: Cost of debt pretax | B4: ='Inputs'!$C$47+'Inputs'!$C$50
A5: Cost of debt aftertax | B5: =B4*(1-'Inputs'!$C$51)
A6: Market equity | B6: ='Inputs'!$C$44
A7: Total debt | B7: ='Inputs'!$C$29+'Inputs'!$C$30+'Inputs'!$C$31
A8: Equity weight | B8: =B6/(B6+B7)
A9: Debt weight | B9: =B7/(B6+B7)
A10: WACC | B10: =B3*B8+B5*B9
A11: Forecast | B11: Year 1 | C11: Year 2 | D11: Year 3 | E11: Year 4 | F11: Year 5
A12: Fiscal year | B12: 2026 | C12: 2027 | D12: 2028 | E12: 2029 | F12: 2030
A13: Revenue growth | B13: ='Inputs'!$C$57 | C13: ='Inputs'!$C$58 | D13: ='Inputs'!$C$59 | E13: ='Inputs'!$C$60 | F13: ='Inputs'!$C$61
A14: Revenue | B14: ='Inputs'!$C$18*(1+B13) | C14: =B14*(1+C13) | D14: =C14*(1+D13) | E14: =D14*(1+E13) | F14: =E14*(1+F13)
A15: EBIT | B15: =B14*'Inputs'!$C$53 | C15: =C14*'Inputs'!$C$53 | D15: =D14*'Inputs'!$C$53 | E15: =E14*'Inputs'!$C$53 | F15: =F14*'Inputs'!$C$53
A16: Tax rate | B16: ='Inputs'!$C$51 | C16: ='Inputs'!$C$51 | D16: ='Inputs'!$C$51 | E16: ='Inputs'!$C$51 | F16: ='Inputs'!$C$51
A17: NOPAT | B17: =B15*(1-B16) | C17: =C15*(1-C16) | D17: =D15*(1-D16) | E17: =E15*(1-E16) | F17: =F15*(1-F16)
A18: D&A | B18: =B14*'Inputs'!$C$54 | C18: =C14*'Inputs'!$C$54 | D18: =D14*'Inputs'!$C$54 | E18: =E14*'Inputs'!$C$54 | F18: =F14*'Inputs'!$C$54
A19: Capex | B19: =B14*'Inputs'!$C$55 | C19: =C14*'Inputs'!$C$55 | D19: =D14*'Inputs'!$C$55 | E19: =E14*'Inputs'!$C$55 | F19: =F14*'Inputs'!$C$55
A20: NWC | B20: =B14*'Inputs'!$C$56 | C20: =C14*'Inputs'!$C$56 | D20: =D14*'Inputs'!$C$56 | E20: =E14*'Inputs'!$C$56 | F20: =F14*'Inputs'!$C$56
A21: Change in NWC | B21: =B20-'Inputs'!$C$72 | C21: =C20-B20 | D21: =D20-C20 | E21: =E20-D20 | F21: =F20-E20
A22: UFCF | B22: =B17+B18-B19-B21 | C22: =C17+C18-C19-C21 | D22: =D17+D18-D19-D21 | E22: =E17+E18-E19-E21 | F22: =F17+F18-F19-F21
A23: PV of UFCF | B23: =B22/(1+$B$10)^1 | C23: =C22/(1+$B$10)^2 | D23: =D22/(1+$B$10)^3 | E23: =E22/(1+$B$10)^4 | F23: =F22/(1+$B$10)^5
A24: PV explicit FCF | B24: =SUM(B23:F23)
A25: Terminal growth | B25: ='Inputs'!$C$52
A26: Terminal value | B26: =F22*(1+$B$25)/($B$10-$B$25)
A27: PV terminal value | B27: =B26/(1+$B$10)^5
A28: Enterprise value | B28: =B24+B27
A29: Cash & investments | B29: ='Inputs'!$C$26+'Inputs'!$C$27+'Inputs'!$C$28
A30: Total debt | B30: =B7
A31: Equity value | B31: =B28+B29-B30
A32: Diluted shares | B32: ='Inputs'!$C$25
A33: Implied share price | B33: =B31/B32
A34: Sensitivity: share price | B34: 0.02 | C34: 0.025 | D34: 0.03
A35: =$B$10-0.01 | B35: =(B$22/(1+$A35)^1+C$22/(1+$A35)^2+D$22/(1+$A35)^3+E$22/(1+$A35)^4+F$22/(1+$A35)^5+$F$22*(1+B$34)/($A35-B$34)/(1+$A35)^5+$B$29-$B$30)/$B$32 | C35: =(B$22/(1+$A35)^1+C$22/(1+$A35)^2+D$22/(1+$A35)^3+E$22/(1+$A35)^4+F$22/(1+$A35)^5+$F$22*(1+C$34)/($A35-C$34)/(1+$A35)^5+$B$29-$B$30)/$B$32 | D35: =(B$22/(1+$A35)^1+C$22/(1+$A35)^2+D$22/(1+$A35)^3+E$22/(1+$A35)^4+F$22/(1+$A35)^5+$F$22*(1+D$34)/($A35-D$34)/(1+$A35)^5+$B$29-$B$30)/$B$32
A36: =$B$10 | B36: =(B$22/(1+$A36)^1+C$22/(1+$A36)^2+D$22/(1+$A36)^3+E$22/(1+$A36)^4+F$22/(1+$A36)^5+$F$22*(1+B$34)/($A36-B$34)/(1+$A36)^5+$B$29-$B$30)/$B$32 | C36: =(B$22/(1+$A36)^1+C$22/(1+$A36)^2+D$22/(1+$A36)^3+E$22/(1+$A36)^4+F$22/(1+$A36)^5+$F$22*(1+C$34)/($A36-C$34)/(1+$A36)^5+$B$29-$B$30)/$B$32 | D36: =(B$22/(1+$A36)^1+C$22/(1+$A36)^2+D$22/(1+$A36)^3+E$22/(1+$A36)^4+F$22/(1+$A36)^5+$F$22*(1+D$34)/($A36-D$34)/(1+$A36)^5+$B$29-$B$30)/$B$32
A37: =$B$10+0.01 | B37: =(B$22/(1+$A37)^1+C$22/(1+$A37)^2+D$22/(1+$A37)^3+E$22/(1+$A37)^4+F$22/(1+$A37)^5+$F$22*(1+B$34)/($A37-B$34)/(1+$A37)^5+$B$29-$B$30)/$B$32 | C37: =(B$22/(1+$A37)^1+C$22/(1+$A37)^2+D$22/(1+$A37)^3+E$22/(1+$A37)^4+F$22/(1+$A37)^5+$F$22*(1+C$34)/($A37-C$34)/(1+$A37)^5+$B$29-$B$30)/$B$32 | D37: =(B$22/(1+$A37)^1+C$22/(1+$A37)^2+D$22/(1+$A37)^3+E$22/(1+$A37)^4+F$22/(1+$A37)^5+$F$22*(1+D$34)/($A37-D$34)/(1+$A37)^5+$B$29-$B$30)/$B$32

Sheet LBO
A1: LBO — illustrative mechanics only; USD bn
A2: Entry / sources & uses | B2: Value
A3: FY2025 EBITDA | B3: ='Inputs'!$C$19+'Inputs'!$C$22
A4: Entry EV/EBITDA | B4: ='Inputs'!$C$62
A5: Entry EV | B5: =B3*B4
A6: Existing net debt | B6: ='Inputs'!$C$29+'Inputs'!$C$30+'Inputs'!$C$31 - ('Inputs'!$C$26+'Inputs'!$C$27+'Inputs'!$C$28)
A7: Seller equity purchase | B7: =B5-B6
A8: Transaction fees | B8: =B5*'Inputs'!$C$69
A9: Opening TLB | B9: =B3*'Inputs'!$C$64
A10: Opening senior notes | B10: =B3*'Inputs'!$C$65
A11: Sponsor equity | B11: =B5+B8-B9-B10
A12: Uses total | B12: =B7+('Inputs'!$C$29+'Inputs'!$C$30+'Inputs'!$C$31)+B8
A13: Sources total | B13: =B9+B10+B11+('Inputs'!$C$26+'Inputs'!$C$27+'Inputs'!$C$28)
A14: Sources less uses | B14: =B13-B12
A15: TLB rate | B15: ='Inputs'!$C$47+'Inputs'!$C$66
A16: Notes rate | B16: ='Inputs'!$C$47+'Inputs'!$C$67
A17: Debt schedule | B17: Year 1 | C17: Year 2 | D17: Year 3 | E17: Year 4 | F17: Year 5
A18: Fiscal year | B18: 2026 | C18: 2027 | D18: 2028 | E18: 2029 | F18: 2030
A19: Revenue | B19: ='DCF'!B14 | C19: ='DCF'!C14 | D19: ='DCF'!D14 | E19: ='DCF'!E14 | F19: ='DCF'!F14
A20: EBIT | B20: ='DCF'!B15 | C20: ='DCF'!C15 | D20: ='DCF'!D15 | E20: ='DCF'!E15 | F20: ='DCF'!F15
A21: D&A | B21: ='DCF'!B18 | C21: ='DCF'!C18 | D21: ='DCF'!D18 | E21: ='DCF'!E18 | F21: ='DCF'!F18
A22: Capex | B22: ='DCF'!B19 | C22: ='DCF'!C19 | D22: ='DCF'!D19 | E22: ='DCF'!E19 | F22: ='DCF'!F19
A23: Change NWC | B23: ='DCF'!B21 | C23: ='DCF'!C21 | D23: ='DCF'!D21 | E23: ='DCF'!E21 | F23: ='DCF'!F21
A24: EBITDA | B24: =B20+B21 | C24: =C20+C21 | D24: =D20+D21 | E24: =E20+E21 | F24: =F20+F21
A25: Beginning TLB | B25: =$B$9 | C25: =B35 | D25: =C35 | E25: =D35 | F25: =E35
A26: Beginning notes | B26: =$B$10 | C26: =B36 | D26: =C36 | E26: =D36 | F26: =E36
A27: TLB interest | B27: =B25*$B$15 | C27: =C25*$B$15 | D27: =D25*$B$15 | E27: =E25*$B$15 | F27: =F25*$B$15
A28: Notes interest | B28: =B26*$B$16 | C28: =C26*$B$16 | D28: =D26*$B$16 | E28: =E26*$B$16 | F28: =F26*$B$16
A29: Total interest | B29: =B27+B28 | C29: =C27+C28 | D29: =D27+D28 | E29: =E27+E28 | F29: =F27+F28
A30: Cash taxes | B30: =MAX(0,(B20-B29)*'Inputs'!$C$51) | C30: =MAX(0,(C20-C29)*'Inputs'!$C$51) | D30: =MAX(0,(D20-D29)*'Inputs'!$C$51) | E30: =MAX(0,(E20-E29)*'Inputs'!$C$51) | F30: =MAX(0,(F20-F29)*'Inputs'!$C$51)
A31: Cash available for debt service | B31: =B20+B21-B22-B23-B30-B29 | C31: =C20+C21-C22-C23-C30-C29 | D31: =D20+D21-D22-D23-D30-D29 | E31: =E20+E21-E22-E23-E30-E29 | F31: =F20+F21-F22-F23-F30-F29
A32: Scheduled TLB amortization | B32: =IF(B18-2025>='Inputs'!$C$76,B25,MIN(B25,$B$9*'Inputs'!$C$68)) | C32: =IF(C18-2025>='Inputs'!$C$76,C25,MIN(C25,$B$9*'Inputs'!$C$68)) | D32: =IF(D18-2025>='Inputs'!$C$76,D25,MIN(D25,$B$9*'Inputs'!$C$68)) | E32: =IF(E18-2025>='Inputs'!$C$76,E25,MIN(E25,$B$9*'Inputs'!$C$68)) | F32: =IF(F18-2025>='Inputs'!$C$76,F25,MIN(F25,$B$9*'Inputs'!$C$68))
A33: TLB cash sweep | B33: =MIN(MAX(0,B25-B32),MAX(0,B31-B32)*'Inputs'!$C$79) | C33: =MIN(MAX(0,C25-C32),MAX(0,C31-C32)*'Inputs'!$C$79) | D33: =MIN(MAX(0,D25-D32),MAX(0,D31-D32)*'Inputs'!$C$79) | E33: =MIN(MAX(0,E25-E32),MAX(0,E31-E32)*'Inputs'!$C$79) | F33: =MIN(MAX(0,F25-F32),MAX(0,F31-F32)*'Inputs'!$C$79)
A34: Notes cash sweep | B34: =MIN(B26,MIN(B26,IF(B18-2025>='Inputs'!$C$77,B26,B26*'Inputs'!$C$78))+MAX(0,B31-B32-B33-MIN(B26,IF(B18-2025>='Inputs'!$C$77,B26,B26*'Inputs'!$C$78)))) | C34: =MIN(C26,MIN(C26,IF(C18-2025>='Inputs'!$C$77,C26,C26*'Inputs'!$C$78))+MAX(0,C31-C32-C33-MIN(C26,IF(C18-2025>='Inputs'!$C$77,C26,C26*'Inputs'!$C$78)))) | D34: =MIN(D26,MIN(D26,IF(D18-2025>='Inputs'!$C$77,D26,D26*'Inputs'!$C$78))+MAX(0,D31-D32-D33-MIN(D26,IF(D18-2025>='Inputs'!$C$77,D26,D26*'Inputs'!$C$78)))) | E34: =MIN(E26,MIN(E26,IF(E18-2025>='Inputs'!$C$77,E26,E26*'Inputs'!$C$78))+MAX(0,E31-E32-E33-MIN(E26,IF(E18-2025>='Inputs'!$C$77,E26,E26*'Inputs'!$C$78)))) | F34: =MIN(F26,MIN(F26,IF(F18-2025>='Inputs'!$C$77,F26,F26*'Inputs'!$C$78))+MAX(0,F31-F32-F33-MIN(F26,IF(F18-2025>='Inputs'!$C$77,F26,F26*'Inputs'!$C$78))))
A35: Ending TLB | B35: =B25-B32-B33 | C35: =C25-C32-C33 | D35: =D25-D32-D33 | E35: =E25-E32-E33 | F35: =F25-F32-F33
A36: Ending notes | B36: =B26-B34 | C36: =C26-C34 | D36: =D26-D34 | E36: =E26-E34 | F36: =F26-F34
A37: Ending total debt | B37: =B35+B36 | C37: =C35+C36 | D37: =D35+D36 | E37: =E35+E36 | F37: =F35+F36
A38: Exit & returns | B38: Value
A39: Exit EBITDA | B39: =F24
A40: Exit multiple | B40: ='Inputs'!$C$63
...

Sheet Comps
A1: Company | B1: Fiscal year | C1: Data provenance tier | D1: Share price (external) | E1: Market cap (external) | F1: Revenue | G1: EBIT | H1: EBITDA | I1: EBITDA margin | J1: Net income | K1: Identified debt* | L1: Identified cash + investments* | M1: Enterprise value* | N1: EV / Revenue* | O1: EV / EBITDA* | P1: P / E | Q1: Peer EV / EBITDA -> AAPL/share | R1: Peer EV / Revenue -> AAPL/share | S1: Balance-sheet flags | T1: EBITDA definition
A2: AAPL | B2: FY2025 | C2: Database provenance (ingested) | D2: ='Inputs'!$C$43 | E2: ='Inputs'!$C$44 | F2: ='Inputs'!$C$18 | G2: ='Inputs'!$C$19 | H2: =G2+'Inputs'!$C$22 | I2: =H2/F2 | J2: ='Inputs'!$C$24 | K2: =SUM('Inputs'!$C$29,'Inputs'!$C$30,'Inputs'!$C$31) | L2: =SUM('Inputs'!$C$26,'Inputs'!$C$27,'Inputs'!$C$28) | M2: =E2+K2-L2 | N2: =M2/F2 | O2: =M2/H2 | P2: =E2/J2 | Q2: =(O2*$H$2-$K$2+$L$2)/'Inputs'!$C$25 | R2: =(N2*$F$2-$K$2+$L$2)/'Inputs'!$C$25 | S2: Complete identified balances | T2: EBIT + combined DepreciationDepletionAndAmortization
A3: MSFT | B3: FY2026 | C3: Analysis-only (capture; not ingested) | D3: ='Inputs'!$C$45 | E3: ='Inputs'!$C$46 | F3: ='Inputs'!$C$34 | G3: ='Inputs'!$C$35 | H3: =G3+'Inputs'!$C$37+'Inputs'!$C$38 | I3: =H3/F3 | J3: ='Inputs'!$C$36 | K3: =SUM('Inputs'!$C$42) | L3: =SUM('Inputs'!$C$39,'Inputs'!$C$40,'Inputs'!$C$41) | M3: =E3+K3-L3 | N3: =M3/F3 | O3: =M3/H3 | P3: =E3/J3 | Q3: =(O3*$H$2-$K$2+$L$2)/'Inputs'!$C$25 | R3: =(N3*$F$2-$K$2+$L$2)/'Inputs'!$C$25 | S3: Commercial paper not found; identified debt only | T3: EBIT + Depreciation + AmortizationOfIntangibleAssets
A4: GOOGL | B4: FY2025 | C4: Database provenance (ingested) | D4: ='Inputs'!$C$124 | E4: ='Inputs'!$C$125 | F4: ='Inputs'!$C$82 | G4: ='Inputs'!$C$83 | H4: =G4+'Inputs'!$C$84 | I4: =H4/F4 | J4: ='Inputs'!$C$85 | K4: =SUM('Inputs'!$C$86) | L4: =SUM('Inputs'!$C$87) | M4: =E4+K4-L4 | N4: =M4/F4 | O4: =M4/H4 | P4: =E4/J4 | Q4: =(O4*$H$2-$K$2+$L$2)/'Inputs'!$C$25 | R4: =(N4*$F$2-$K$2+$L$2)/'Inputs'!$C$25 | S4: Commercial paper reported as 0.000; aggregate cash tag includes cash | T4: EBIT + Depreciation only; no intangible amortization tag identified
A5: AMZN | B5: FY2025 | C5: Database provenance (ingested) | D5: ='Inputs'!$C$126 | E5: ='Inputs'!$C$127 | F5: ='Inputs'!$C$89 | G5: ='Inputs'!$C$90 | H5: =G5+'Inputs'!$C$91+'Inputs'!$C$92 | I5: =H5/F5 | J5: ='Inputs'!$C$93 | K5: =SUM('Inputs'!$C$94) | L5: =SUM('Inputs'!$C$95) | M5: =E5+K5-L5 | N5: =M5/F5 | O5: =M5/H5 | P5: =E5/J5 | Q5: =(O5*$H$2-$K$2+$L$2)/'Inputs'!$C$25 | R5: =(N5*$F$2-$K$2+$L$2)/'Inputs'!$C$25 | S5: Commercial paper not found; identified debt only | T5: EBIT + Depreciation + AmortizationOfIntangibleAssets; excludes finance-lease ROU amortization
A6: META | B6: FY2025 | C6: Analysis-only (capture; not ingested) | D6: ='Inputs'!$C$128 | E6: ='Inputs'!$C$129 | F6: ='Inputs'!$C$97 | G6: ='Inputs'!$C$98 | H6: =G6+'Inputs'!$C$99+'Inputs'!$C$100 | I6: =H6/F6 | J6: ='Inputs'!$C$101 | K6: =SUM('Inputs'!$C$105) | L6: =SUM('Inputs'!$C$106) | M6: =E6+K6-L6 | N6: =M6/F6 | O6: =M6/H6 | P6: =E6/J6 | Q6: =(O6*$H$2-$K$2+$L$2)/'Inputs'!$C$25 | R6: =(N6*$F$2-$K$2+$L$2)/'Inputs'!$C$25 | S6: Current debt and commercial paper not found; identified debt is noncurrent only | T6: EBIT + Depreciation + AmortizationOfIntangibleAssets; excludes finance-lease ROU amortization
A7: NVDA | B7: FY2026 | C7: Analysis-only (capture; not ingested) | D7: ='Inputs'!$C$130 | E7: ='Inputs'!$C$131 | F7: ='Inputs'!$C$107 | G7: ='Inputs'!$C$108 | H7: =G7+'Inputs'!$C$109+'Inputs'!$C$110 | I7: =H7/F7 | J7: ='Inputs'!$C$111 | K7: =SUM('Inputs'!$C$112) | L7: =SUM('Inputs'!$C$116) | M7: =E7+K7-L7 | N7: =M7/F7 | O7: =M7/H7 | P7: =E7/J7 | Q7: =(O7*$H$2-$K$2+$L$2)/'Inputs'!$C$25 | R7: =(N7*$F$2-$K$2+$L$2)/'Inputs'!$C$25 | S7: FY2026 investments and commercial paper not found; identified cash only | T7: EBIT + Depreciation + AmortizationOfIntangibleAssets; excludes finance-lease ROU amortization
A8: TSLA | B8: FY2025 | C8: Analysis-only (capture; not ingested) | D8: ='Inputs'!$C$132 | E8: ='Inputs'!$C$133 | F8: ='Inputs'!$C$117 | G8: ='Inputs'!$C$118 | H8: =G8+'Inputs'!$C$119 | I8: =H8/F8 | J8: ='Inputs'!$C$120 | K8: =SUM('Inputs'!$C$121) | L8: =SUM('Inputs'!$C$122) | M8: =E8+K8-L8 | N8: =M8/F8 | O8: =M8/H8 | P8: =E8/J8 | Q8: =(O8*$H$2-$K$2+$L$2)/'Inputs'!$C$25 | R8: =(N8*$F$2-$K$2+$L$2)/'Inputs'!$C$25 | S8: Commercial paper not found; identified debt only | T8: EBIT + Depreciation only; no intangible amortization tag identified
A10: * Enterprise values and multiples use identified balances only. Missing balances are unresolved, not assumed zero; see balance-sheet flags and the consolidated README appendix.

Sheet Football Field
A1: Method | B1: Low ($/share) | C1: High ($/share) | D1: Apple market price ($/share) | E1: Low - market ($) | F1: High - market ($) | G1: Chart base | H1: Chart span | I1: Notes
A2: DCF sensitivity | B2: =MIN('DCF'!B35:D37) | C2: =MAX('DCF'!B35:D37) | D2: ='Inputs'!$C$43 | E2: =B2-D2 | F2: =C2-D2 | G2: =B2 | H2: =C2-B2 | I2: Day 3 WACC / terminal-growth sensitivity grid
A3: Materiality-screened EV / EBITDA (AAPL + MSFT* + GOOGL) | B3: =MIN('Comps'!Q2,'Comps'!Q3,'Comps'!Q4) | C3: =MAX('Comps'!Q2,'Comps'!Q3,'Comps'!Q4) | D3: ='Inputs'!$C$43 | E3: =B3-D3 | F3: =C3-D3 | G3: =B3 | H3: =C3-B3 | I3: Apple and Alphabet complete; Microsoft re-included using stated FY2026 CommercialPaper = $0.000bn assumption based on FY2025.
A4: Materiality-screened EV / Revenue (AAPL + MSFT* + GOOGL) | B4: =MIN('Comps'!R2,'Comps'!R3,'Comps'!R4) | C4: =MAX('Comps'!R2,'Comps'!R3,'Comps'!R4) | D4: ='Inputs'!$C$43 | E4: =B4-D4 | F4: =C4-D4 | G4: =B4 | H4: =C4-B4 | I4: Apple and Alphabet complete; Microsoft re-included using stated FY2026 CommercialPaper = $0.000bn assumption based on FY2025.
A5: Microsoft P/E (legacy point) | B5: =('Inputs'!$C$75*'Comps'!$J$2)/'Inputs'!$C$25 | C5: =('Inputs'!$C$75*'Comps'!$J$2)/'Inputs'!$C$25 | D5: ='Inputs'!$C$43 | E5: =B5-D5 | F5: =C5-D5 | G5: =B5 | H5: =C5-B5 | I5: Microsoft P/E is an equity multiple, not an EV multiple; retained as the prior point estimate.
A6: LBO ability-to-pay | B6: ='LBO'!B54 | C6: ='LBO'!B54 | D6: ='Inputs'!$C$43 | E6: =B6-D6 | F6: =C6-D6 | G6: =B6 | H6: =C6-B6 | I6: Illustrative mechanics only; not a realistic deal thesis
I7: * Microsoft re-included using a stated zero/near-zero assumption for CommercialPaper, based on the FY2025 value of $0.000bn at 2025-06-30. Amazon, Meta, NVIDIA, and Tesla remain excluded; see note below.
A8: Materiality screen: Microsoft alone is re-included among previously excluded issuers, using FY2025 CommercialPaper of $0.000bn (2025-06-30) as an explicit assumption for missing FY2026 CommercialPaper, not a reported FY2026 fact. Amazon and Tesla CommercialPaper, and Meta current debt/commercial paper, have no adjacent low same-tag value; they remain excluded. NVIDIA FY2026 MarketableSecuritiesCurrent is missing; its FY2025 same-tag value was $34.621bn (2025-01-26), not low/near-zero, so NVIDIA remains excluded. This inclusion/exclusion rule is based on fact materiality, separately from ingestion status: Amazon is ingested but excluded; Microsoft is capture-only but re-included under assumption. NVIDIA and Meta remain excluded.
